Traceback (most recent call last):
  File "/home/rkostov/.conda/envs/IS/lib/python3.9/site-packages/jupyter_cache/executors/utils.py", line 51, in single_nb_execution
    executenb(
  File "/home/rkostov/.conda/envs/IS/lib/python3.9/site-packages/nbclient/client.py", line 1112, in execute
    return NotebookClient(nb=nb, resources=resources, km=km, **kwargs).execute()
  File "/home/rkostov/.conda/envs/IS/lib/python3.9/site-packages/nbclient/util.py", line 74, in wrapped
    return just_run(coro(*args, **kwargs))
  File "/home/rkostov/.conda/envs/IS/lib/python3.9/site-packages/nbclient/util.py", line 53, in just_run
    return loop.run_until_complete(coro)
  File "/home/rkostov/.conda/envs/IS/lib/python3.9/asyncio/base_events.py", line 642, in run_until_complete
    return future.result()
  File "/home/rkostov/.conda/envs/IS/lib/python3.9/site-packages/nbclient/client.py", line 553, in async_execute
    await self.async_execute_cell(
  File "/home/rkostov/.conda/envs/IS/lib/python3.9/site-packages/nbclient/client.py", line 857, in async_execute_cell
    self._check_raise_for_error(cell, exec_reply)
  File "/home/rkostov/.conda/envs/IS/lib/python3.9/site-packages/nbclient/client.py", line 760, in _check_raise_for_error
    raise CellExecutionError.from_cell_and_msg(cell, exec_reply_content)
nbclient.exceptions.CellExecutionError: An error occurred while executing the following cell:
------------------
from keras.models import Model
from keras.layers import Dense, Input, Dropout, LSTM, Activation
from keras.layers.embeddings import Embedding
from sklearn.metrics import classification_report, f1_score, log_loss, precision_score, recall_score

import csv
import matplotlib.pyplot as plt
import numpy as np
import pandas as pd

np.random.seed(1)
------------------

[0;31m---------------------------------------------------------------------------[0m
[0;31mModuleNotFoundError[0m                       Traceback (most recent call last)
[0;32m<ipython-input-1-2cf47b7ff89c>[0m in [0;36m<module>[0;34m[0m
[0;32m----> 1[0;31m [0;32mfrom[0m [0mkeras[0m[0;34m.[0m[0mmodels[0m [0;32mimport[0m [0mModel[0m[0;34m[0m[0;34m[0m[0m
[0m[1;32m      2[0m [0;32mfrom[0m [0mkeras[0m[0;34m.[0m[0mlayers[0m [0;32mimport[0m [0mDense[0m[0;34m,[0m [0mInput[0m[0;34m,[0m [0mDropout[0m[0;34m,[0m [0mLSTM[0m[0;34m,[0m [0mActivation[0m[0;34m[0m[0;34m[0m[0m
[1;32m      3[0m [0;32mfrom[0m [0mkeras[0m[0;34m.[0m[0mlayers[0m[0;34m.[0m[0membeddings[0m [0;32mimport[0m [0mEmbedding[0m[0;34m[0m[0;34m[0m[0m
[1;32m      4[0m [0;32mfrom[0m [0msklearn[0m[0;34m.[0m[0mmetrics[0m [0;32mimport[0m [0mclassification_report[0m[0;34m,[0m [0mf1_score[0m[0;34m,[0m [0mlog_loss[0m[0;34m,[0m [0mprecision_score[0m[0;34m,[0m [0mrecall_score[0m[0;34m[0m[0;34m[0m[0m
[1;32m      5[0m [0;34m[0m[0m

[0;31mModuleNotFoundError[0m: No module named 'keras'
ModuleNotFoundError: No module named 'keras'

